Workbook
Name ROOFERS: Crews!$A$1:$A$21
Name STORY: 'Story Fee'!$A$2:$A$5
Name CREW: Crews!$A$1:$A$21
Name MANAGER: PMs!$A$1:$A$25
Name DECKING: OSB!$A$1:$A$4
Name SLOPE: 'Slope Pricing'!$A$1:$A$13
Name STORIES: 'Story Fee'!$A$1:$A$5
Name EXTRA: 'Additional Items'!$A$1:$A$7
Name EXTRAS: 'Additional Items'!$A$1:$A$10
Name ROOFINGCREW: Crews!$A$1:$A$27
Name ROOFCREW: Crews!$A$1:$A$26

Sheet INVOICE
B1: ROOFING INVOICE
B3: INSTALL DATE: | C3: =IFERROR(__xludf.DUMMYFUNCTION("IFERROR(VLOOKUP($H$11,IMPORTRANGE(""https://docs.google.com/spreadsheets/d/1IKntoB-BFY0-vjMH94c9Md4wtLQz8cMBxYJbfK9AAjE/edit?resourcekey=null#gid=0"",""PROJECT TRACKING!B3:N""),11,false))"),45139.0) -> 45139
B5: ROOFING CREW: | D5: =IFERROR(__xludf.DUMMYFUNCTION("IFERROR(VLOOKUP($H$11,IMPORTRANGE(""https://docs.google.com/spreadsheets/d/1IKntoB-BFY0-vjMH94c9Md4wtLQz8cMBxYJbfK9AAjE/edit?resourcekey=null#gid=0"",""PROJECT TRACKING!B3:N""),13,false)) "),"JOSE ACOSTA") -> JOSE ACOSTA
D6: =IFERROR(VLOOKUP($H$11,DATABASE!$A:$AW,2,0)) -> DM
B7: PROJECT MANAGER: | D7: =IFERROR(__xludf.DUMMYFUNCTION("IFERROR(VLOOKUP($D$6,IMPORTRANGE(""https://docs.google.com/spreadsheets/d/1IKntoB-BFY0-vjMH94c9Md4wtLQz8cMBxYJbfK9AAjE/edit?resourcekey=null#gid=0"",""PMs!A2:G50""),7,false))"),"DUSTIN MOORE ") -> DUSTIN MOORE
B9: CUSTOMER NAME: | D9: =IFERROR(__xludf.DUMMYFUNCTION("IFERROR(VLOOKUP($H$11,IMPORTRANGE(""https://docs.google.com/spreadsheets/d/1IKntoB-BFY0-vjMH94c9Md4wtLQz8cMBxYJbfK9AAjE/edit?resourcekey=null#gid=0"",""PROJECT TRACKING!B3:N""),2,false)) ")," HANSEN") -> HANSEN | G9: SUPPLIER: | H9: =IFERROR(__xludf.DUMMYFUNCTION("IFERROR(VLOOKUP($H$11,IMPORTRANGE(""https://docs.google.com/spreadsheets/d/1IKntoB-BFY0-vjMH94c9Md4wtLQz8cMBxYJbfK9AAjE/edit?resourcekey=null#gid=0"",""PROJECT TRACKING!B3:N""),12,false)) "),"ABC") -> ABC
B11: ADDRESS: | C11: =IFERROR(__xludf.DUMMYFUNCTION("IFERROR(VLOOKUP($H$11,IMPORTRANGE(""https://docs.google.com/spreadsheets/d/1IKntoB-BFY0-vjMH94c9Md4wtLQz8cMBxYJbfK9AAjE/edit?resourcekey=null#gid=0"",""PROJECT TRACKING!B3:N""),4,false)) "),"1802 PALO PINTO DR") -> 1802 PALO PINTO DR | G11: =IFERROR(__xludf.DUMMYFUNCTION("IMPORTRANGE(""https://docs.google.com/spreadsheets/d/1IKntoB-BFY0-vjMH94c9Md4wtLQz8cMBxYJbfK9AAjE/edit?resourcekey=null#gid=0"",""PROJECT TRACKING!B1"")"),"PO #") -> PO # | H11: 2559
B14: ACTUAL BODY SQUARES (%0 EV) | E14: 43.34 | G14: TOTAL BODY ORDRED W/ WASTE
B15: WASTE FACTOR | E15: 0.25 | G15: =IF(E14="","",E14+(E14*E15)) -> 54.175
D17: PER UNIT | E17: ACTUAL SQ | F17: W/ WASTE | H17: SUB TOTAL
B18: SLOPE: | C18: 10/12 | D18: 90 | E18: 43.66 | F18: =IF(E18="","",E18+(E18*$E$15)) -> 54.575 | H18: =D18*F18 -> 4911.75
B19: SLOPE: | C19: 10/12 | D19: =IFNA(VLOOKUP(C19,'Slope Pricing'!$A$1:B31,2,FALSE),"") -> 80 | F19: =IF(E19="","",E19+(E19*$E$15)) | H19: =D19*F19 -> 0
B20: SLOPE: | D20: =IFNA(VLOOKUP(C20,'Slope Pricing'!$A$1:B32,2,FALSE),"") | F20: =IF(E20="","",E20+(E20*$E$15)) | H20: =D20*F20 -> 0
B21: SLOPE: | D21: =IFNA(VLOOKUP(C21,'Slope Pricing'!$A$1:B33,2,FALSE),"") | F21: =IF(E21="","",E21+(E21*$E$15)) | H21: =D21*F21 -> 0
B22: SLOPE: | D22: =IFNA(VLOOKUP(C22,'Slope Pricing'!$A$1:B34,2,FALSE),"") | F22: =IF(E22="","",E22+(E22*$E$15)) | H22: =D22*F22 -> 0
B23: SLOPE: | D23: =IFNA(VLOOKUP(C23,'Slope Pricing'!$A$1:B35,2,FALSE),"") | F23: =IF(E23="","",E23+(E23*$E$15)) | H23: =D23*F23 -> 0
B24: SLOPE: | D24: =IFNA(VLOOKUP(C24,'Slope Pricing'!$A$1:B36,2,FALSE),"") | F24: =IF(E24="","",E24+(E24*$E$15)) | H24: =D24*F24 -> 0
B25: SLOPE: | D25: =IFNA(VLOOKUP(C25,'Slope Pricing'!$A$1:B37,2,FALSE),"") | F25: =IF(E25="","",E25+(E25*$E$15)) | H25: =D25*F25 -> 0
B26: SLOPE: | D26: =IFNA(VLOOKUP(C26,'Slope Pricing'!$A$1:B38,2,FALSE),"") | F26: =IF(E26="","",E26+(E26*$E$15)) | H26: =D26*F26 -> 0
B27: SLOPE: | D27: =IFNA(VLOOKUP(C27,'Slope Pricing'!$A$1:B39,2,FALSE),"") | F27: =IF(E27="","",E27+(E27*$E$15)) | H27: =D27*F27 -> 0
B28: HOTSHOT | D28: =IFNA(VLOOKUP(C28,'Slope Pricing'!$A$1:B40,2,FALSE),"") | F28: =E28 | H28: =D28*E28 -> 0
B29: HIP & RIDGE | C29: FLAT RATE | D29: 70 | E29: 4.18 | F29: =E29 -> 4.18 | H29: =D29*E29 -> 292.6
B30: LEFTOVER | C30: 10/12 | D30: =IFNA(VLOOKUP(C30,'Slope Pricing'!$A$1:B30,2,FALSE),"") -> 80 | E30: 1 | F30: =IF(E30="","",E30+(E30*$E$15)) -> 1.25 | H30: =(-D30*E30) -> -80
B32: ACTUAL SQUARES ENTERED: | E32: =SUM(E18:E28) -> 43.66
B33: JOB TOTAL BODY WITH WASTE (MINUS LEFTOVER) | F33: =(SUM(F18:F28)-F30) -> 53.325
E35: PRICE | F35: OTY
B36: DECKING: | E36: =IFNA(VLOOKUP(C36,OSB!A1:B2,2,FALSE),"") | H36: =E36*F36 -> 0
B37: STORIES: | C37: 2.0 STORY | E37: 6.75 | F37: =E32 -> 43.66 | H37: =E37*F37 -> 294.705
B38: EXTRA: | E38: =IFNA(VLOOKUP(C38,'Additional Items'!$A$1:$B$10,2,FALSE),0) -> 0 | H38: =E38*F38 -> 0
B39: EXTRA: | E39: =IFNA(VLOOKUP(C39,'Additional Items'!$A$1:$B$10,2,FALSE),0) -> 0 | H39: =E39*F39 -> 0
B40: EXTRA: | E40: =IFNA(VLOOKUP(C40,'Additional Items'!$A$1:$B$10,2,FALSE),0) -> 0 | H40: =E40*F40 -> 0
B41: CHARGEBACK:
B44: NOTES: | C44: ordered: 163bdls/13ridge/5starter=181total returned 3 | G44: TOTAL: | H44: =SUM(H18:H30,H36:H40,-H41) -> 5419.055
B45: Insurance estimate:43/43 no waste
B46: eagleview:43/54sq.
B47: *LABOR PAID ON WASTE*
B48: *PRICE INCLUDES R&R DRIP EDGE, R&R ALL VENTILATION, R&R EXISTING FELT*

Sheet DATABASE
A1: =C:C -> PO # | B1: =IFERROR(__xludf.DUMMYFUNCTION("IMPORTRANGE(""https://docs.google.com/spreadsheets/d/1IKntoB-BFY0-vjMH94c9Md4wtLQz8cMBxYJbfK9AAjE/edit?resourcekey=null#gid=0"",""PROJECT TRACKING!A:B"")"),"PM") -> PM | C1: =IFERROR(__xludf.DUMMYFUNCTION("""COMPUTED_VALUE"""),"PO #") -> PO #
A2: =C:C
A3: =C:C -> 2301 | B3: =IFERROR(__xludf.DUMMYFUNCTION("""COMPUTED_VALUE"""),"CS") -> CS | C3: =IFERROR(__xludf.DUMMYFUNCTION("""COMPUTED_VALUE"""),2301.0) -> 2301
A4: =C:C -> 2302 | B4: =IFERROR(__xludf.DUMMYFUNCTION("""COMPUTED_VALUE"""),"DM") -> DM | C4: =IFERROR(__xludf.DUMMYFUNCTION("""COMPUTED_VALUE"""),2302.0) -> 2302
A5: =C:C -> 2303 | B5: =IFERROR(__xludf.DUMMYFUNCTION("""COMPUTED_VALUE"""),"DM") -> DM | C5: =IFERROR(__xludf.DUMMYFUNCTION("""COMPUTED_VALUE"""),2303.0) -> 2303
A6: =C:C -> 2304 | B6: =IFERROR(__xludf.DUMMYFUNCTION("""COMPUTED_VALUE"""),"DM") -> DM | C6: =IFERROR(__xludf.DUMMYFUNCTION("""COMPUTED_VALUE"""),2304.0) -> 2304
A7: =C:C -> 2305 | B7: =IFERROR(__xludf.DUMMYFUNCTION("""COMPUTED_VALUE"""),"CS") -> CS | C7: =IFERROR(__xludf.DUMMYFUNCTION("""COMPUTED_VALUE"""),2305.0) -> 2305
A8: =C:C -> 2306 | B8: =IFERROR(__xludf.DUMMYFUNCTION("""COMPUTED_VALUE"""),"CS") -> CS | C8: =IFERROR(__xludf.DUMMYFUNCTION("""COMPUTED_VALUE"""),2306.0) -> 2306
A9: =C:C -> 2307 | B9: =IFERROR(__xludf.DUMMYFUNCTION("""COMPUTED_VALUE"""),"CS") -> CS | C9: =IFERROR(__xludf.DUMMYFUNCTION("""COMPUTED_VALUE"""),2307.0) -> 2307
A10: =C:C -> 2308 | B10: =IFERROR(__xludf.DUMMYFUNCTION("""COMPUTED_VALUE"""),"CS") -> CS | C10: =IFERROR(__xludf.DUMMYFUNCTION("""COMPUTED_VALUE"""),2308.0) -> 2308
A11: =C:C -> 2309 | B11: =IFERROR(__xludf.DUMMYFUNCTION("""COMPUTED_VALUE"""),"DM") -> DM | C11: =IFERROR(__xludf.DUMMYFUNCTION("""COMPUTED_VALUE"""),2309.0) -> 2309
A12: =C:C -> 2310 | B12: =IFERROR(__xludf.DUMMYFUNCTION("""COMPUTED_VALUE"""),"CS") -> CS | C12: =IFERROR(__xludf.DUMMYFUNCTION("""COMPUTED_VALUE"""),2310.0) -> 2310
A13: =C:C -> 2311 | B13: =IFERROR(__xludf.DUMMYFUNCTION("""COMPUTED_VALUE"""),"DM") -> DM | C13: =IFERROR(__xludf.DUMMYFUNCTION("""COMPUTED_VALUE"""),2311.0) -> 2311
A14: =C:C -> 2312 | B14: =IFERROR(__xludf.DUMMYFUNCTION("""COMPUTED_VALUE"""),"DM") -> DM | C14: =IFERROR(__xludf.DUMMYFUNCTION("""COMPUTED_VALUE"""),2312.0) -> 2312
A15: =C:C -> 2313 | B15: =IFERROR(__xludf.DUMMYFUNCTION("""COMPUTED_VALUE"""),"DM") -> DM | C15: =IFERROR(__xludf.DUMMYFUNCTION("""COMPUTED_VALUE"""),2313.0) -> 2313
A16: =C:C -> 2314 | B16: =IFERROR(__xludf.DUMMYFUNCTION("""COMPUTED_VALUE"""),"DM") -> DM | C16: =IFERROR(__xludf.DUMMYFUNCTION("""COMPUTED_VALUE"""),2314.0) -> 2314
A17: =C:C -> 2315 | B17: =IFERROR(__xludf.DUMMYFUNCTION("""COMPUTED_VALUE"""),"DM") -> DM | C17: =IFERROR(__xludf.DUMMYFUNCTION("""COMPUTED_VALUE"""),2315.0) -> 2315
A18: =C:C -> 2316 | B18: =IFERROR(__xludf.DUMMYFUNCTION("""COMPUTED_VALUE"""),"DM") -> DM | C18: =IFERROR(__xludf.DUMMYFUNCTION("""COMPUTED_VALUE"""),2316.0) -> 2316
A19: =C:C -> 2317 | B19: =IFERROR(__xludf.DUMMYFUNCTION("""COMPUTED_VALUE"""),"CS") -> CS | C19: =IFERROR(__xludf.DUMMYFUNCTION("""COMPUTED_VALUE"""),2317.0) -> 2317
A20: =C:C -> 2318 | B20: =IFERROR(__xludf.DUMMYFUNCTION("""COMPUTED_VALUE"""),"DM") -> DM | C20: =IFERROR(__xludf.DUMMYFUNCTION("""COMPUTED_VALUE"""),2318.0) -> 2318
A21: =C:C -> 2319 | B21: =IFERROR(__xludf.DUMMYFUNCTION("""COMPUTED_VALUE"""),"DM") -> DM | C21: =IFERROR(__xludf.DUMMYFUNCTION("""COMPUTED_VALUE"""),2319.0) -> 2319
A22: =C:C -> 2320 | B22: =IFERROR(__xludf.DUMMYFUNCTION("""COMPUTED_VALUE"""),"DM") -> DM | C22: =IFERROR(__xludf.DUMMYFUNCTION("""COMPUTED_VALUE"""),2320.0) -> 2320
A23: =C:C -> 2321 | B23: =IFERROR(__xludf.DUMMYFUNCTION("""COMPUTED_VALUE"""),"DM") -> DM | C23: =IFERROR(__xludf.DUMMYFUNCTION("""COMPUTED_VALUE"""),2321.0) -> 2321
A24: =C:C -> 2322 | B24: =IFERROR(__xludf.DUMMYFUNCTION("""COMPUTED_VALUE"""),"DM") -> DM | C24: =IFERROR(__xludf.DUMMYFUNCTION("""COMPUTED_VALUE"""),2322.0) -> 2322
A25: =C:C -> 2323 | B25: =IFERROR(__xludf.DUMMYFUNCTION("""COMPUTED_VALUE"""),"CS") -> CS | C25: =IFERROR(__xludf.DUMMYFUNCTION("""COMPUTED_VALUE"""),2323.0) -> 2323
A26: =C:C -> 2324 | B26: =IFERROR(__xludf.DUMMYFUNCTION("""COMPUTED_VALUE"""),"DM") -> DM | C26: =IFERROR(__xludf.DUMMYFUNCTION("""COMPUTED_VALUE"""),2324.0) -> 2324
A27: =C:C -> 2325 | B27: =IFERROR(__xludf.DUMMYFUNCTION("""COMPUTED_VALUE"""),"DM") -> DM | C27: =IFERROR(__xludf.DUMMYFUNCTION("""COMPUTED_VALUE"""),2325.0) -> 2325
A28: =C:C -> 2326 | B28: =IFERROR(__xludf.DUMMYFUNCTION("""COMPUTED_VALUE"""),"CS") -> CS | C28: =IFERROR(__xludf.DUMMYFUNCTION("""COMPUTED_VALUE"""),2326.0) -> 2326
A29: =C:C -> 2327 | B29: =IFERROR(__xludf.DUMMYFUNCTION("""COMPUTED_VALUE"""),"DM") -> DM | C29: =IFERROR(__xludf.DUMMYFUNCTION("""COMPUTED_VALUE"""),2327.0) -> 2327
A30: =C:C -> 2328 | B30: =IFERROR(__xludf.DUMMYFUNCTION("""COMPUTED_VALUE"""),"DM") -> DM | C30: =IFERROR(__xludf.DUMMYFUNCTION("""COMPUTED_VALUE"""),2328.0) -> 2328
A31: =C:C -> 2329 | B31: =IFERROR(__xludf.DUMMYFUNCTION("""COMPUTED_VALUE"""),"CS") -> CS | C31: =IFERROR(__xludf.DUMMYFUNCTION("""COMPUTED_VALUE"""),2329.0) -> 2329
A32: =C:C -> 2330 | B32: =IFERROR(__xludf.DUMMYFUNCTION("""COMPUTED_VALUE"""),"CS") -> CS | C32: =IFERROR(__xludf.DUMMYFUNCTION("""COMPUTED_VALUE"""),2330.0) -> 2330
A33: =C:C -> 2331 | B33: =IFERROR(__xludf.DUMMYFUNCTION("""COMPUTED_VALUE"""),"LM") -> LM | C33: =IFERROR(__xludf.DUMMYFUNCTION("""COMPUTED_VALUE"""),2331.0) -> 2331
A34: =C:C -> 2332 | B34: =IFERROR(__xludf.DUMMYFUNCTION("""COMPUTED_VALUE"""),"DM") -> DM | C34: =IFERROR(__xludf.DUMMYFUNCTION("""COMPUTED_VALUE"""),2332.0) -> 2332
A35: =C:C -> 2333 | B35: =IFERROR(__xludf.DUMMYFUNCTION("""COMPUTED_VALUE"""),"CS") -> CS | C35: =IFERROR(__xludf.DUMMYFUNCTION("""COMPUTED_VALUE"""),2333.0) -> 2333
A36: =C:C -> 2334 | B36: =IFERROR(__xludf.DUMMYFUNCTION("""COMPUTED_VALUE"""),"CS") -> CS | C36: =IFERROR(__xludf.DUMMYFUNCTION("""COMPUTED_VALUE"""),2334.0) -> 2334
A37: =C:C -> 2335 | B37: =IFERROR(__xludf.DUMMYFUNCTION("""COMPUTED_VALUE"""),"DM") -> DM | C37: =IFERROR(__xludf.DUMMYFUNCTION("""COMPUTED_VALUE"""),2335.0) -> 2335
A38: =C:C -> 2336 | B38: =IFERROR(__xludf.DUMMYFUNCTION("""COMPUTED_VALUE"""),"LJ") -> LJ | C38: =IFERROR(__xludf.DUMMYFUNCTION("""COMPUTED_VALUE"""),2336.0) -> 2336
A39: =C:C -> 2337 | B39: =IFERROR(__xludf.DUMMYFUNCTION("""COMPUTED_VALUE"""),"LJ") -> LJ | C39: =IFERROR(__xludf.DUMMYFUNCTION("""COMPUTED_VALUE"""),2337.0) -> 2337
A40: =C:C -> 2338 | B40: =IFERROR(__xludf.DUMMYFUNCTION("""COMPUTED_VALUE"""),"CS") -> CS | C40: =IFERROR(__xludf.DUMMYFUNCTION("""COMPUTED_VALUE"""),2338.0) -> 2338
...

Sheet PMs
A1: CHRIS STEDMAN - DECKS BY DESIGN
A2: DUSTIN MOORE - MOORE GROUP
A3: TRAVIS BRIDGES

Sheet Crews
A1: MICKEY'S CREW - JUAN ARROYO
A5: EMILIANO RAMOS-HERNANDEZ
A10: OMAR RAMIREZ
A11: LUIS MARTINEZ
A13: JOE GARCIA
A14: MIGUEL HERRERA - GYG RESTORATIONS
A15: JOSE ACOSTA

Sheet Slope Pricing
A1: 6/12 | B1: 60
A2: 7/12 | B2: =B1+5 -> 65
A3: 8/12 | B3: =B2+5 -> 70
A4: 9/12 | B4: =B3+5 -> 75
A5: 10/12 | B5: =B4+5 -> 80
A6: 11/12 | B6: =B5+5 -> 85
A7: 12/12 | B7: =B6+5 -> 90
A8: 13/12 | B8: =B7+5 -> 95
A9: 14/12 | B9: =B8+5 -> 100
A10: 15/12 | B10: =B9+5 -> 105
A11: 16/12 | B11: =B10+5 -> 110
A12: 17/12 | B12: =B11+5 -> 115
A13: 18/12 | B13: =B12+5 -> 120
... A21: 26/12 | B21: =B20+5 -> 160
A23: H/R FLAT RATE | B23: 60

Sheet OSB
A1: OSB DECKING = $20/SHEET | B1: 20
A2: OSB DECKING = $60/SQ | B2: 60

Sheet Story Fee
A1: 1.0 STORY | B1: 0
A2: 1.5 STORY | B2: 3
A3: 2.0 STORY | B3: 5
A4: 2.5 STORY | B4: 8
A5: 3.0 STORY | B5: 0

Sheet Additional Items
A1: 2ND LAYER SHINGLE REMOVAL | B1: 10 | E1: Supplier | F1: BFS
A2: 2ND FELT REMOVAL | B2: 5 | F2: ABC
A3: 3RD FELT REMOVAL | B3: 10 | F3: BEACON
A4: CHIMNEY CRICKET | B4: 125 | F4: RSG
A5: R&R SKYLIGHT | B5: 100
A6: FLASH CHIMNEY | B6: 60
A7: COUNTER FLASH | B7: 100
A8: FLASH SKYLIGHT | B8: 60
A9: MISC, FLASHING | B9: 50
A10: PICK UP | B10: 75
